weight=0
embed_into_distance=2
acceptable_target_blocks=0
dimensions=4,17,8

street_templates=CobblestoneStreetHumansPlus.tml
street_density=8
level_interior=1
building_templates=NONE
walk_height=10
min_length=150
max_length=300
building_interval=30
make_buildings=1

#default towers
tower_rule=1
default_tower_weight=1
spawner_rule=0,40,321
circular_probability=0.5
square_min_height=14
square_max_height=20
square_min_width=8
square_max_width=10
square_roof_styles=Crenel,Steep,Shallow
circular_tower_min_height=14
circular_tower_max_height=20
circular_tower_min_width=8
circular_tower_max_width=12
circular_tower_roof_styles=Crenel

#stone brick rules for wall bulk and towers
rule1=0,100,98-0,98-0,98-0,98-0,98-0,98-0,98-0,98-0,98-0,98-0,98-0,98-0,98-0,98-0,98-1,98-2    
rule2=0,100,98-1,98-1,98-1,98-0,98-0,98-0,98-0,98-0,98-0,98-0,98-0,98-0,98-0,98-0,98-0,98-2  
rule3=0,100,98-1,98-1,98-1,98-1,98-1,98-1,98-1,98-1,98-1,98-0,98-0,98-0,98-0,98-0,98-0,98-2
rule4=0,100,319-5   #stairs

#roofway
rule5=0,100,5
rule6=0,100,85
rule7=0,100,50-5
rule8=0,100,53-0   
rule9=0,100,53-1
rule10=0,100,313





layer
0,0,8,5,5,9,0,0
0,8,5,5,5,5,9,0
8,0,0,0,0,0,0,9
0,0,0,0,0,0,0,0
0,0,0,0,0,0,0,0
0,0,0,0,0,0,0,0
2,0,0,0,0,0,0,2
2,1,1,1,1,1,1,2
2,1,1,1,1,1,1,2
2,1,1,1,1,1,1,2
3,1,1,1,1,1,1,3
3,1,1,1,1,1,1,3
3,1,1,1,1,1,1,3
3,1,1,1,1,1,1,3
3,1,1,1,1,1,1,3
3,1,1,1,1,1,1,3
3,1,1,1,1,1,1,3
endlayer

layer
0,0,8,5,5,9,0,0
0,8,5,5,5,5,9,0
8,0,0,0,0,0,0,9
6,0,0,0,0,0,0,6
6,0,0,0,0,0,0,6
6,0,0,0,0,0,0,6
2,0,0,0,0,0,0,2
2,1,1,1,1,1,1,2
2,1,1,1,1,1,1,2
2,1,1,1,1,1,1,2
3,1,1,1,1,1,1,3
3,1,1,1,1,1,1,3
3,1,1,1,1,1,1,3
3,1,1,1,1,1,1,3
3,1,1,1,1,1,1,3
3,1,1,1,1,1,1,3
3,1,1,1,1,1,1,3
endlayer

layer
0,0,8,5,5,9,0,0
0,8,5,5,5,5,9,0
8,0,0,0,0,0,0,9
0,0,0,0,0,0,0,0
0,0,0,0,0,0,0,0
0,0,0,0,0,0,0,0
2,0,0,0,0,0,0,2
2,1,1,1,1,1,1,2
2,1,1,1,1,1,1,2
2,1,1,1,1,1,1,2
3,1,1,1,1,1,1,3
3,1,1,1,1,1,1,3
3,1,1,1,1,1,1,3
3,1,1,1,1,1,1,3
3,1,1,1,1,1,1,3
3,1,1,1,1,1,1,3
3,1,1,1,1,1,1,3
endlayer


layer
0,0,8,5,5,9,0,0
0,8,5,5,5,5,9,0
8,0,0,0,0,0,0,9
0,0,0,0,0,0,0,0
0,0,0,0,0,0,0,0
7,0,0,0,0,0,0,7
2,0,0,0,0,0,0,2
2,1,1,1,1,1,1,2
2,1,1,1,1,1,1,2
2,1,1,1,1,1,1,2
3,1,1,1,1,1,1,3
3,1,1,1,1,1,1,3
3,1,1,1,1,1,1,3
3,1,1,1,1,1,1,3
3,1,1,1,1,1,1,3
3,1,1,1,1,1,1,3
3,1,1,1,1,1,1,3
endlayer


layer:shifted
0,0,8,5,5,9,0,0
0,8,5,5,5,5,9,0
8,5,0,0,0,0,5,9
6,0,0,0,0,0,0,6
6,0,0,0,0,0,0,6
6,0,0,0,0,0,0,6
2,4,4,4,4,4,4,2
2,1,1,1,1,1,1,2
2,1,1,1,1,1,1,2
2,1,1,1,1,1,1,2
3,1,1,1,1,1,1,3
3,1,1,1,1,1,1,3
3,1,1,1,1,1,1,3
3,1,1,1,1,1,1,3
3,1,1,1,1,1,1,3
3,1,1,1,1,1,1,3
3,1,1,1,1,1,1,3
endlayer

layer:shifted_up
0,0,8,5,5,9,0,0
0,8,5,5,5,5,9,0
8,5,0,0,0,0,5,9
0,0,0,0,0,0,0,0
0,0,0,0,0,0,0,0
0,0,0,0,0,0,0,0
2,4,4,4,4,4,4,2
2,1,1,1,1,1,1,2
2,1,1,1,1,1,1,2
2,1,1,1,1,1,1,2
3,1,1,1,1,1,1,3
3,1,1,1,1,1,1,3
3,1,1,1,1,1,1,3
3,1,1,1,1,1,1,3
3,1,1,1,1,1,1,3
3,1,1,1,1,1,1,3
3,1,1,1,1,1,1,3
endlayer

layer:shifted_down
0,0,8,5,5,9,0,0
0,8,5,5,5,5,9,0
8,5,0,0,0,0,5,9
0,0,0,0,0,0,0,0
0,0,0,0,0,0,0,0
0,0,0,0,0,0,0,0
2,4,4,4,4,4,4,2
2,1,1,1,1,1,1,2
2,1,1,1,1,1,1,2
2,1,1,1,1,1,1,2
3,1,1,1,1,1,1,3
3,1,1,1,1,1,1,3
3,1,1,1,1,1,1,3
3,1,1,1,1,1,1,3
3,1,1,1,1,1,1,3
3,1,1,1,1,1,1,3
3,1,1,1,1,1,1,3
endlayer

layer:shifted_left
0,0,8,5,5,9,0,0
0,8,5,5,5,5,9,0
8,5,0,0,0,0,5,9
0,0,0,0,0,0,0,0
0,0,0,0,0,0,0,0
0,0,0,0,0,0,0,0
2,4,4,4,4,4,4,2
2,1,1,1,1,1,1,2
2,1,1,1,1,1,1,2
2,1,1,1,1,1,1,2
3,1,1,1,1,1,1,3
3,1,1,1,1,1,1,3
3,1,1,1,1,1,1,3
3,1,1,1,1,1,1,3
3,1,1,1,1,1,1,3
3,1,1,1,1,1,1,3
3,1,1,1,1,1,1,3
endlayer

layer:shifted_right
0,0,8,5,5,9,0,0
0,8,5,5,5,5,9,0
8,5,0,0,0,0,5,9
0,0,0,0,0,0,0,0
0,0,0,0,0,0,0,0
0,0,0,0,0,0,0,0
2,4,4,4,4,4,4,2
2,1,1,1,1,1,1,2
2,1,1,1,1,1,1,2
2,1,1,1,1,1,1,2
3,1,1,1,1,1,1,3
3,1,1,1,1,1,1,3
3,1,1,1,1,1,1,3
3,1,1,1,1,1,1,3
3,1,1,1,1,1,1,3
3,1,1,1,1,1,1,3
3,1,1,1,1,1,1,3
endlayer

layer:base
3,1,1,1,1,1,1,3
endlayer